<?xml version="1.0" ?>
<sdf version="1.8">
  <world name="dlo_workspace">
    <!-- Physics -->
    <physics name="1ms" type="ignored">
      <max_step_size>0.001</max_step_size>
      <real_time_factor>1.0</real_time_factor>
    </physics>

    <!-- Plugins -->
    <plugin filename="ignition-gazebo-physics-system" name="ignition::gazebo::systems::Physics"/>
    <plugin filename="ignition-gazebo-user-commands-system" name="ignition::gazebo::systems::UserCommands"/>
    <plugin filename="ignition-gazebo-scene-broadcaster-system" name="ignition::gazebo::systems::SceneBroadcaster"/>
    <plugin filename="ignition-gazebo-sensors-system" name="ignition::gazebo::systems::Sensors">
      <render_engine>ogre2</render_engine>
    </plugin>
    <plugin filename="ignition-gazebo-contact-system" name="ignition::gazebo::systems::Contact"/>

    <!-- Lighting -->
    <light type="directional" name="sun">
      <cast_shadows>true</cast_shadows>
      <pose>0 0 10 0 0 0</pose>
      <diffuse>0.8 0.8 0.8 1</diffuse>
      <specular>0.2 0.2 0.2 1</specular>
      <attenuation>
        <range>1000</range>
        <constant>0.9</constant>
        <linear>0.01</linear>
        <quadratic>0.001</quadratic>
      </attenuation>
      <direction>-0.5 0.1 -0.9</direction>
    </light>

    <light type="point" name="fill_light">
      <pose>1 1 3 0 0 0</pose>
      <diffuse>0.5 0.5 0.5 1</diffuse>
      <specular>0.1 0.1 0.1 1</specular>
      <attenuation>
        <range>20</range>
        <constant>0.5</constant>
        <linear>0.01</linear>
        <quadratic>0.01</quadratic>
      </attenuation>
    </light>

    <!-- Ground Plane -->
    <model name="ground_plane">
      <static>true</static>
      <link name="link">
        <collision name="collision">
          <geometry>
            <plane>
              <normal>0 0 1</normal>
              <size>100 100</size>
            </plane>
          </geometry>
        </collision>
        <visual name="visual">
          <geometry>
            <plane>
              <normal>0 0 1</normal>
              <size>100 100</size>
            </plane>
          </geometry>
          <material>
            <ambient>0.8 0.8 0.8 1</ambient>
            <diffuse>0.8 0.8 0.8 1</diffuse>
          </material>
        </visual>
      </link>
    </model>

    <!-- Workspace Table -->
    <model name="table">
      <static>true</static>
      <pose>0.5 0 0.375 0 0 0</pose>
      <link name="table_link">
        <collision name="collision">
          <geometry>
            <box><size>1.2 0.8 0.75</size></box>
          </geometry>
        </collision>
        <visual name="visual">
          <geometry>
            <box><size>1.2 0.8 0.75</size></box>
          </geometry>
          <material>
            <ambient>0.6 0.5 0.4 1</ambient>
            <diffuse>0.6 0.5 0.4 1</diffuse>
          </material>
        </visual>
      </link>
    </model>

    <!-- RGBD Camera mounted above workspace -->
    <model name="rgbd_camera">
      <static>true</static>
      <pose>0.5308947503950723 0.030109485611943067 1.3374 -1.5707963 0 0</pose>
      <link name="camera_link">
        <visual name="visual">
          <geometry>
            <box><size>0.05 0.1 0.03</size></box>
          </geometry>
          <material>
            <ambient>0.2 0.2 0.2 1</ambient>
            <diffuse>0.3 0.3 0.3 1</diffuse>
          </material>
        </visual>
        <sensor name="rgbd_camera" type="rgbd_camera">
          <always_on>1</always_on>
          <update_rate>15</update_rate>
          <camera>
            <horizontal_fov>1.2217</horizontal_fov>
            <image>
              <width>1280</width>
              <height>720</height>
              <format>R8G8B8</format>
            </image>
            <clip>
              <near>0.1</near>
              <far>10.0</far>
            </clip>
            <depth_camera>
              <clip>
                <near>0.1</near>
                <far>10.0</far>
              </clip>
            </depth_camera>
          </camera>
          <topic>camera</topic>
        </sensor>
      </link>
    </model>

    <!-- Simple DLO model: chain of blue links connected by revolute joints -->
    <model name="dlo">
      <pose>0.3 0 0.76 0 0 0</pose>

      <!-- Link 0 (base) -->
      <link name="link_0">
        <pose>0 0 0 0 0 0</pose>
        <inertial>
          <mass>0.005</mass>
          <inertia>
            <ixx>1e-7</ixx><iyy>1e-6</iyy><izz>1e-6</izz>
          </inertia>
        </inertial>
        <collision name="collision">
          <geometry>
            <cylinder><radius>0.004</radius><length>0.02</length></cylinder>
          </geometry>
        </collision>
        <visual name="visual">
          <geometry>
            <cylinder><radius>0.004</radius><length>0.02</length></cylinder>
          </geometry>
          <material>
            <ambient>0.0 0.2 0.8 1</ambient>
            <diffuse>0.0 0.3 0.9 1</diffuse>
          </material>
        </visual>
      </link>

      <!-- Generate 19 more links with joints -->
      <link name="link_1">
        <pose>0.02 0 0 0 1.5707963 0</pose>
        <inertial><mass>0.005</mass><inertia><ixx>1e-7</ixx><iyy>1e-6</iyy><izz>1e-6</izz></inertia></inertial>
        <collision name="collision"><geometry><cylinder><radius>0.004</radius><length>0.02</length></cylinder></geometry></collision>
        <visual name="visual"><geometry><cylinder><radius>0.004</radius><length>0.02</length></cylinder></geometry>
          <material><ambient>0.0 0.2 0.8 1</ambient><diffuse>0.0 0.3 0.9 1</diffuse></material></visual>
      </link>
      <joint name="joint_0_1" type="revolute">
        <parent>link_0</parent><child>link_1</child>
        <pose>-0.01 0 0 0 0 0</pose>
        <axis><xyz>0 1 0</xyz><limit><lower>-1.57</lower><upper>1.57</upper></limit>
          <dynamics><damping>0.01</damping></dynamics></axis>
      </joint>

      <link name="link_2">
        <pose>0.04 0 0 0 1.5707963 0</pose>
        <inertial><mass>0.005</mass><inertia><ixx>1e-7</ixx><iyy>1e-6</iyy><izz>1e-6</izz></inertia></inertial>
        <collision name="collision"><geometry><cylinder><radius>0.004</radius><length>0.02</length></cylinder></geometry></collision>
        <visual name="visual"><geometry><cylinder><radius>0.004</radius><length>0.02</length></cylinder></geometry>
          <material><ambient>0.0 0.2 0.8 1</ambient><diffuse>0.0 0.3 0.9 1</diffuse></material></visual>
      </link>
      <joint name="joint_1_2" type="revolute">
        <parent>link_1</parent><child>link_2</child>
        <pose>-0.01 0 0 0 0 0</pose>
        <axis><xyz>0 1 0</xyz><limit><lower>-1.57</lower><upper>1.57</upper></limit>
          <dynamics><damping>0.01</damping></dynamics></axis>
      </joint>

      <link name="link_3">
        <pose>0.06 0 0 0 1.5707963 0</pose>
        <inertial><mass>0.005</mass><inertia><ixx>1e-7</ixx><iyy>1e-6</iyy><izz>1e-6</izz></inertia></inertial>
        <collision name="collision"><geometry><cylinder><radius>0.004</radius><length>0.02</length></cylinder></geometry></collision>
        <visual name="visual"><geometry><cylinder><radius>0.004</radius><length>0.02</length></cylinder></geometry>
          <material><ambient>0.0 0.2 0.8 1</ambient><diffuse>0.0 0.3 0.9 1</diffuse></material></visual>
      </link>
      <joint name="joint_2_3" type="revolute">
        <parent>link_2</parent><child>link_3</child>
        <pose>-0.01 0 0 0 0 0</pose>
        <axis><xyz>0 1 0</xyz><limit><lower>-1.57</lower><upper>1.57</upper></limit>
          <dynamics><damping>0.01</damping></dynamics></axis>
      </joint>

      <link name="link_4">
        <pose>0.08 0 0 0 1.5707963 0</pose>
        <inertial><mass>0.005</mass><inertia><ixx>1e-7</ixx><iyy>1e-6</iyy><izz>1e-6</izz></inertia></inertial>
        <collision name="collision"><geometry><cylinder><radius>0.004</radius><length>0.02</length></cylinder></geometry></collision>
        <visual name="visual"><geometry><cylinder><radius>0.004</radius><length>0.02</length></cylinder></geometry>
          <material><ambient>0.0 0.2 0.8 1</ambient><diffuse>0.0 0.3 0.9 1</diffuse></material></visual>
      </link>
      <joint name="joint_3_4" type="revolute">
        <parent>link_3</parent><child>link_4</child>
        <pose>-0.01 0 0 0 0 0</pose>
        <axis><xyz>0 1 0</xyz><limit><lower>-1.57</lower><upper>1.57</upper></limit>
          <dynamics><damping>0.01</damping></dynamics></axis>
      </joint>

      <link name="link_5">
        <pose>0.10 0 0 0 1.5707963 0</pose>
        <inertial><mass>0.005</mass><inertia><ixx>1e-7</ixx><iyy>1e-6</iyy><izz>1e-6</izz></inertia></inertial>
        <collision name="collision"><geometry><cylinder><radius>0.004</radius><length>0.02</length></cylinder></geometry></collision>
        <visual name="visual"><geometry><cylinder><radius>0.004</radius><length>0.02</length></cylinder></geometry>
          <material><ambient>0.0 0.2 0.8 1</ambient><diffuse>0.0 0.3 0.9 1</diffuse></material></visual>
      </link>
      <joint name="joint_4_5" type="revolute">
        <parent>link_4</parent><child>link_5</child>
        <pose>-0.01 0 0 0 0 0</pose>
        <axis><xyz>0 1 0</xyz><limit><lower>-1.57</lower><upper>1.57</upper></limit>
          <dynamics><damping>0.01</damping></dynamics></axis>
      </joint>

      <link name="link_6">
        <pose>0.12 0 0 0 1.5707963 0</pose>
        <inertial><mass>0.005</mass><inertia><ixx>1e-7</ixx><iyy>1e-6</iyy><izz>1e-6</izz></inertia></inertial>
        <collision name="collision"><geometry><cylinder><radius>0.004</radius><length>0.02</length></cylinder></geometry></collision>
        <visual name="visual"><geometry><cylinder><radius>0.004</radius><length>0.02</length></cylinder></geometry>
          <material><ambient>0.0 0.2 0.8 1</ambient><diffuse>0.0 0.3 0.9 1</diffuse></material></visual>
      </link>
      <joint name="joint_5_6" type="revolute">
        <parent>link_5</parent><child>link_6</child>
        <pose>-0.01 0 0 0 0 0</pose>
        <axis><xyz>0 1 0</xyz><limit><lower>-1.57</lower><upper>1.57</upper></limit>
          <dynamics><damping>0.01</damping></dynamics></axis>
      </joint>

      <link name="link_7">
        <pose>0.14 0 0 0 1.5707963 0</pose>
        <inertial><mass>0.005</mass><inertia><ixx>1e-7</ixx><iyy>1e-6</iyy><izz>1e-6</izz></inertia></inertial>
        <collision name="collision"><geometry><cylinder><radius>0.004</radius><length>0.02</length></cylinder></geometry></collision>
        <visual name="visual"><geometry><cylinder><radius>0.004</radius><length>0.02</length></cylinder></geometry>
          <material><ambient>0.0 0.2 0.8 1</ambient><diffuse>0.0 0.3 0.9 1</diffuse></material></visual>
      </link>
      <joint name="joint_6_7" type="revolute">
        <parent>link_6</parent><child>link_7</child>
        <pose>-0.01 0 0 0 0 0</pose>
        <axis><xyz>0 1 0</xyz><limit><lower>-1.57</lower><upper>1.57</upper></limit>
          <dynamics><damping>0.01</damping></dynamics></axis>
      </joint>

      <link name="link_8">
        <pose>0.16 0 0 0 1.5707963 0</pose>
        <inertial><mass>0.005</mass><inertia><ixx>1e-7</ixx><iyy>1e-6</iyy><izz>1e-6</izz></inertia></inertial>
        <collision name="collision"><geometry><cylinder><radius>0.004</radius><length>0.02</length></cylinder></geometry></collision>
        <visual name="visual"><geometry><cylinder><radius>0.004</radius><length>0.02</length></cylinder></geometry>
          <material><ambient>0.0 0.2 0.8 1</ambient><diffuse>0.0 0.3 0.9 1</diffuse></material></visual>
      </link>
      <joint name="joint_7_8" type="revolute">
        <parent>link_7</parent><child>link_8</child>
        <pose>-0.01 0 0 0 0 0</pose>
        <axis><xyz>0 1 0</xyz><limit><lower>-1.57</lower><upper>1.57</upper></limit>
          <dynamics><damping>0.01</damping></dynamics></axis>
      </joint>

      <link name="link_9">
        <pose>0.18 0 0 0 1.5707963 0</pose>
        <inertial><mass>0.005</mass><inertia><ixx>1e-7</ixx><iyy>1e-6</iyy><izz>1e-6</izz></inertia></inertial>
        <collision name="collision"><geometry><cylinder><radius>0.004</radius><length>0.02</length></cylinder></geometry></collision>
        <visual name="visual"><geometry><cylinder><radius>0.004</radius><length>0.02</length></cylinder></geometry>
          <material><ambient>0.0 0.2 0.8 1</ambient><diffuse>0.0 0.3 0.9 1</diffuse></material></visual>
      </link>
      <joint name="joint_8_9" type="revolute">
        <parent>link_8</parent><child>link_9</child>
        <pose>-0.01 0 0 0 0 0</pose>
        <axis><xyz>0 1 0</xyz><limit><lower>-1.57</lower><upper>1.57</upper></limit>
          <dynamics><damping>0.01</damping></dynamics></axis>
      </joint>
    </model>

  </world>
</sdf>
